<?xml version="1.0"?>

<!-- XML namespaces -->
<robot xmlns:sensor="http://playerstage.sourceforge.net/gazebo/xmlschema/#sensor"
       xmlns:controller="http://playerstage.sourceforge.net/gazebo/xmlschema/#controller"
       xmlns:interface="http://playerstage.sourceforge.net/gazebo/xmlschema/#interface"
       xmlns:xacro="http://ros.org/wiki/xacro">

  <xacro:property name="wrist_sensor_offset" value="0.0"/>
  <!-- ============================   arm_upper   ============================ -->
  
  <xacro:macro name="arm_upper" params="base_link disable_mesh:=false r_hand_link:=r_hand_link">
  
  <link name="${base_link}">
    <inertial>
      <origin xyz="0.0 0 0" rpy="0 0 0"/>
      <mass value="1.257"/>
      <inertia ixx="0.00787462" ixy="1.86853e-06" ixz="0.000109278" iyy="0.00564958" iyz="4.77298e-06" izz="0.00724112"/>
    </inertial>
  </link>
  <link name="r_shoulder_link">
    <xacro:unless value="${disable_mesh}"> <visual>
      <origin xyz="0 0 0" rpy="0 0 0"/>
      <geometry>
        <mesh filename="package://seed_r7_description/meshes/typeC_arm/Assembly_HA-ST42_D.DAE" scale="1 1 1"/>
      </geometry>
    </visual> </xacro:unless>
    <xacro:unless value="${disable_mesh}"> <collision>
      <origin xyz="0 0 0" rpy="0 0 0"/>
      <geometry>
        <mesh filename="package://seed_r7_description/meshes/typeC_arm/Assembly_HA-ST42_D.DAE" scale="1 1 1"/>
      </geometry>
    </collision> </xacro:unless>
    <inertial>
      <origin xyz="0 0 0" rpy="0 0 0"/>
      <mass value="0.153989"/>
      <inertia ixx="7.20502e-05" ixy="-3.97093e-11" ixz="1.25067e-06" iyy="9.14657e-05" iyz="1.33728e-10" izz="7.99165e-05"/>
    </inertial>
  </link>
  <link name="r_upperarm_link">
    <xacro:unless value="${disable_mesh}"> <visual>
      <origin xyz="0 0 0" rpy="0 0 0"/>
      <geometry>
        <mesh filename="package://seed_r7_description/meshes/typeC_arm/SARM_frame_upper_C.DAE" scale="1 1 1"/>
      </geometry>
    </visual> </xacro:unless>
    <xacro:unless value="${disable_mesh}"> <collision>
      <origin xyz="0 0 0" rpy="0 0 0"/>
      <geometry>
        <mesh filename="package://seed_r7_description/meshes/typeC_arm/SARM_frame_upper_C.DAE" scale="1 1 1"/>
      </geometry>
    </collision> </xacro:unless>
    <inertial>
      <origin xyz="0 0 0" rpy="0 0 0"/>
      <mass value="0.571747"/>
      <inertia ixx="0.00600119" ixy="-3.64499e-07" ixz="-0.000211137" iyy="0.00635549" iyz="-1.81458e-07" izz="0.000838023"/>
    </inertial>
  </link>
  <link name="r_elbow_link">
    <xacro:unless value="${disable_mesh}"> <visual>
      <origin xyz="-0.035 0 0.035" rpy="0 0 0"/>
      <geometry>
        <mesh filename="package://seed_r7_description/meshes/typeC_arm/ARM_frame_elbow_F3.DAE" scale="1 1 1"/>
      </geometry>
    </visual> </xacro:unless>
    <xacro:unless value="${disable_mesh}"> <collision>
      <origin xyz="-0.00 0 -0.0" rpy="0 0 0"/>
      <geometry>
        <mesh filename="package://seed_r7_description/meshes/typeC_arm/ARM_frame_elbow_F3.DAE" scale="1 1 1"/>
      </geometry>
    </collision> </xacro:unless>
    <inertial>
      <origin xyz="0 0 0" rpy="0 0 0"/>
      <mass value="0.520191"/>
      <inertia ixx="0.000719932" ixy="-1.77744e-08" ixz="1.34362e-06" iyy="0.000716013" iyz="-6.86778e-06" izz="0.000201071"/>
    </inertial>
  </link>
  <link name="r_wrist_y_link">
    <xacro:unless value="${disable_mesh}"> <visual>
      <origin xyz="0 0 0" rpy="0 0 0"/>
      <geometry>
        <mesh filename="package://seed_r7_description/meshes/typeC_arm/Assy_ARM_P3_F3.DAE" scale="1 1 1"/>
      </geometry>
    </visual> </xacro:unless>
    <xacro:unless value="${disable_mesh}"> <collision>
      <origin xyz="0 0 0" rpy="0 0 0"/>
      <geometry>
        <mesh filename="package://seed_r7_description/meshes/typeC_arm/Assy_ARM_P3_F3.DAE" scale="1 1 1"/>
      </geometry>
    </collision> </xacro:unless>
    <inertial>
      <origin xyz="0 0 0" rpy="0 0 0"/>
      <mass value="0.148468"/>
      <inertia ixx="0.000283315" ixy="1.0793e-07" ixz="-7.05555e-10" iyy="0.000294049" iyz="-6.32939e-09" izz="0.00010571"/>
    </inertial>
  </link>
  <link name="r_wrist_p_link">
    <inertial>
      <mass value="0" />
      <origin xyz="0 0 0" rpy="0 -0 0"/>
      <inertia ixx="0" ixy="0" ixz="0" iyy="0" iyz="0" izz="0"/>
    </inertial>
  </link>
  <joint name="r_shoulder_y_joint" type="revolute">
    <origin xyz="0.0 0 0.01" rpy="0 0 0"/>
    <parent link="${base_link}"/>
  	<axis xyz="0.0 0.0 1.0"/>
    <child link="r_shoulder_link"/>
    <dynamics damping="0.1"/>
  <limit lower="-1.57" upper="1.57" effort="3.14" velocity ="0.6"/>
  </joint>
  <joint name="r_shoulder_p_joint" type="revolute">
    <origin xyz="0 0 0.1205" rpy="0 0 0"/>
	 <axis xyz="0.0 1.0 0.0"/>    
	 <parent link="r_shoulder_link"/>
    <child link="r_upperarm_link"/>
    <dynamics damping="0.1"/>
  <limit lower="0" upper="1.5707" effort="100" velocity="0.6" />
  </joint>
  <joint name="r_elbow_joint" type="revolute">
    <origin xyz="0.035 0 0.335" rpy="0 0 0"/>
    <axis xyz="0.0 1.0 0.0"/>
    <parent link="r_upperarm_link"/>
    <child link="r_elbow_link"/>
    <dynamics damping="0.1"/>
  <limit lower="0" upper="3.14" effort="100" velocity="0.6" />
  </joint>
  <!-- For arm r_wrist_y_joint limit needs to set from -2.0[rad] to 2.0[rad] to grasp side.
  Please check seed_r7_description/urdf/aero_arm_typec-->
  <joint name="r_wrist_y_joint" type="revolute">
    <origin xyz="-0.035 0 0.0755" rpy="0 0 0"/>
	  <axis xyz="0.0 0.0 1.0"/>
    <parent link="r_elbow_link"/>
    <child link="r_wrist_y_link"/>
    <dynamics damping="0.1"/>
  <limit lower="-3.3" upper="0.5" effort="100" velocity="1.5" />
  </joint>
  <joint name="r_wrist_p_joint" type="revolute">
    <origin xyz="0 0 0.195" rpy="0 0 0"/>
	  <axis xyz="1.0 0.0 0.0"/>
    <parent link="r_wrist_y_link"/>
    <child link="r_wrist_p_link"/>
    <dynamics damping="0.1"/>
  <limit lower="-0.6" upper="1.57" effort="100" velocity="1.3" />
  </joint>
  <joint name="r_wrist_r_joint" type="revolute">
    <origin xyz="0 0 0" rpy="0 3.14 0"/>
	  <axis xyz="0.0 1.0 0.0"/>
    <parent link="r_wrist_p_link"/>
    <child link="${r_hand_link}"/>
    <dynamics damping="0.1"/>
    <limit lower="-0.1" upper="0.1" effort="100" velocity="1.3" />
  </joint>
  </xacro:macro>
</robot>
