<?xml version="1.0"?>

<!-- XML namespaces -->
<robot name="noid_upper_typeg_otama" xmlns:xacro="http://ros.org/wiki/xacro">

  <xacro:include filename="$(find seed_r7_description)/urdf/gazebo.xacro" />

  <xacro:property name="wrist_sensor_offset" value="0.0"/>

  <xacro:macro name="noid_upper" params="base_link disable_mesh:=false r_hand_link:=r_hand_link l_hand_link:=l_hand_link">
  <!-- ============================   typeG_upper   ============================ -->
  <link name="${base_link}">
    <xacro:unless value="${disable_mesh}"> <visual>
      <origin xyz="0 0 0" rpy="0 0 0"/>
      <geometry>
        <mesh filename="package://seed_r7_description/meshes/typeG_otama_upperbody/waist_link.dae" scale="1 1 1" />
      </geometry>
    </visual> </xacro:unless>
    <xacro:unless value="${disable_mesh}"> <collision>
      <origin xyz="0 0 0" rpy="0 -0 0"/>
      <geometry>
        <mesh filename="package://seed_r7_description/meshes/typeG_otama_upperbody/waist_link.dae" scale="1 1 1" />
      </geometry>
    </collision> </xacro:unless>
    <inertial>
      <mass value="1.257" />
      <origin xyz="0 0 0.0" rpy="0 0 0"/>
      <inertia ixx="0.034" ixy="0" ixz="0" iyy="0.034" iyz="0" izz="0.018"/>
    </inertial>
  </link>
  <xacro:gazebo_link_reference link_name="${base_link}" />

  <link name="hip_sphere_link">
    <xacro:unless value="${disable_mesh}"> <visual>
      <origin xyz="0 0 0" rpy="0 0 0"/>
      <geometry>
        <mesh filename="package://seed_r7_description/meshes/typeG_otama_upperbody/hip_sphere_link.dae" scale="1 1 1" />
      </geometry>
    </visual> </xacro:unless>
    <xacro:unless value="${disable_mesh}"> <collision>
      <origin xyz="0 0 0.132" rpy="0 0 0"/>
      <geometry>
        <!-- <mesh filename="package://seed_r7_description/meshes/typeG_otama_upperbody/hip_sphere_link.dae" scale="1 1 1" /> -->
        <sphere radius="0.05"/>
      </geometry>
    </collision> </xacro:unless>
    <inertial>
      <mass value="1.257" />
      <origin xyz="0 0 0.042" rpy="0 -0 0"/>
      <!-- inertia ixx="0.034" ixy="0" ixz="0" iyy="0.034" iyz="0" izz="0.018"/ -->
      <!-- just fixed for gazebo / reduce inertia-->
      <inertia ixx="0.01" ixy="0" ixz="0" iyy="0.01" iyz="0" izz="0.007"/>
    </inertial>
  </link>
  <xacro:gazebo_link_reference link_name="hip_sphere_link" />

  <link name="hip_center">
    <xacro:unless value="${disable_mesh}"> <visual>
      <origin xyz="0 0 0" rpy="0 0 0"/>
      <geometry>
        <mesh filename="package://seed_r7_description/meshes/typeG_otama_upperbody/hip_center_link.dae" scale="1 1 1" />
      </geometry>
    </visual> </xacro:unless>
    <xacro:unless value="${disable_mesh}"> <collision>
      <origin xyz="0 0 0" rpy="0 0 0"/>
      <geometry>
        <!-- <mesh filename="package://seed_r7_description/meshes/typeG_otama_upperbody/hip_center_link.dae" scale="1 1 1" /> -->
        <sphere radius="0.05"/>
      </geometry>
    </collision> </xacro:unless>
    <inertial>
      <mass value="0.1" />
      <origin xyz="0 0 0" rpy="0 0 0"/>
      <inertia ixx="0.003" ixy="0" ixz="0" iyy="0.003" iyz="0" izz="0.003"/>
    </inertial>
  </link>
  <xacro:gazebo_link_reference link_name="hip_center" />

  <link name="body_link">
    <xacro:unless value="${disable_mesh}"> <visual>
      <origin xyz="0 0 0" rpy="0 0 0"/>
      <geometry>
        <mesh filename="package://seed_r7_description/meshes/typeG_otama_upperbody/body_link.dae" scale="1 1 1" />
      </geometry>
    </visual> </xacro:unless>
    <xacro:unless value="${disable_mesh}"> <collision>
      <origin xyz="0 0 0" rpy="0 0 0"/>
      <geometry>
        <mesh filename="package://seed_r7_description/meshes/typeG_otama_upperbody/body_link.dae" scale="1 1 1" />
      </geometry>
    </collision> </xacro:unless>
    <inertial>
      <mass value="10.551" />
      <origin xyz="0 0 0.22" rpy="0 -0 0"/>
      <inertia ixx="0.13" ixy="0" ixz="0" iyy="0.12" iyz="0" izz="0.114"/>
    </inertial>
  </link>
  <xacro:gazebo_link_reference link_name="body_link" />

  <link name="l_shoulder_link">
    <xacro:unless value="${disable_mesh}"> <visual>
      <origin xyz="0 0 0" rpy="0 0 0"/>
      <geometry>
        <mesh filename="package://seed_r7_description/meshes/typeG_otama_upperbody/l_shoulder_link.dae" scale="1 1 1" />
      </geometry>
    </visual> </xacro:unless>
    <xacro:unless value="${disable_mesh}"> <collision>
      <origin xyz="0 0 0" rpy="0 0 0"/>
      <geometry>
        <mesh filename="package://seed_r7_description/meshes/typeG_otama_upperbody/l_shoulder_link.dae" scale="1 1 1" />
      </geometry>
    </collision> </xacro:unless>
    <inertial>
      <mass value="0.242" />
      <!--origin xyz="0 0.02 0" rpy="0 -0 0"/>
      <inertia ixx="0.000228" ixy="0" ixz="0" iyy="0.000148" iyz="0" izz="0.000263"/-->
      <!-- just fixed for gazebo / increase inertia-->
      <origin xyz="0 0.02 0.015" rpy="0 -0 0"/>
      <inertia ixx="0.00133" ixy="0" ixz="0" iyy="0.001" iyz="0" izz="0.00133"/>
    </inertial>
  </link>
  <xacro:gazebo_link_reference link_name="l_shoulder_link" />

  <link name="l_shoulder_center">
    <xacro:unless value="${disable_mesh}"> <visual>
      <origin xyz="0 0 0" rpy="0 -0 0"/>
      <geometry>
        <mesh filename="package://seed_r7_description/meshes/typeG_otama_upperbody/l_shoulder_center_link.dae" scale="1 1 1" />
      </geometry>
    </visual> </xacro:unless>
    <xacro:unless value="${disable_mesh}"> <collision>
      <origin xyz="0 0 0" rpy="0 -0 0"/>
      <geometry>
        <mesh filename="package://seed_r7_description/meshes/typeG_otama_upperbody/l_shoulder_center_link.dae" scale="1 1 1" />
      </geometry>
    </collision> </xacro:unless>
    <inertial>
      <mass value="0.744" />
      <!--origin xyz="0 0.01 0" rpy="0 -0 0"/-->
      <origin xyz="0 -0.01 -0.06" rpy="0 -0 0"/>
      <inertia ixx="0.000841" ixy="0" ixz="0" iyy="0.000835" iyz="0" izz="0.000304"/>
    </inertial>
  </link>
  <xacro:gazebo_link_reference link_name="l_shoulder_center" />

  <link name="l_upperarm_link">
    <xacro:unless value="${disable_mesh}"> <visual>
      <origin xyz="0 0 0" rpy="0 -0 0"/>
      <geometry>
        <mesh filename="package://seed_r7_description/meshes/typeG_otama_upperbody/upperarm_link.dae" scale="1 1 1" />
      </geometry>
    </visual> </xacro:unless>
    <xacro:unless value="${disable_mesh}"> <collision>
      <origin xyz="0 0 0" rpy="0 -0 0"/>
      <geometry>
        <mesh filename="package://seed_r7_description/meshes/typeG_otama_upperbody/upperarm_link.dae" scale="1 1 1" />
      </geometry>
    </collision> </xacro:unless>
    <inertial>
      <mass value="0.574" />
      <!--origin xyz="0.005 0 -0.0654" rpy="0 -0 0"/>
      <inertia ixx="0.00114" ixy="0" ixz="0" iyy="0.00117" iyz="0" izz="0.000269"/-->
      <!-- fix for gazebo -->
      <origin xyz="0.005 0 -0.0654" rpy="0 -0 0"/>
      <inertia ixx="0.00214" ixy="0" ixz="0" iyy="0.00217" iyz="0" izz="0.003"/>
    </inertial>
  </link>
  <xacro:gazebo_link_reference link_name="l_upperarm_link" />

  <link name="l_elbow_virtual_link">
    <inertial>
      <mass value="0.001" />
      <origin xyz="0 0 0" rpy="0 0 0"/>
      <inertia ixx="0.01" ixy="0" ixz="0" iyy="0.01" iyz="0" izz="0.01"/>
    </inertial>
  </link>
  <xacro:gazebo_link_reference link_name="l_elbow_virtual_link" />

  <link name="l_elbow_virtual_link_dummy">
    <inertial>
      <mass value="0.001" />
      <origin xyz="0 0 0" rpy="0 0 0"/>
      <inertia ixx="0.01" ixy="0" ixz="0" iyy="0.01" iyz="0" izz="0.01"/>
    </inertial>
  </link>
  <xacro:gazebo_link_reference link_name="l_elbow_virtual_link_dummy" />

  <link name="l_elbow_middle_link">
    <xacro:unless value="${disable_mesh}"> <visual>
      <origin xyz="0 0 0" rpy="0 -0 0"/>
      <geometry>
        <mesh filename="package://seed_r7_description/meshes/typeG_otama_upperbody/elbow_middle_link.dae" scale="1 1 1" />
      </geometry>
    </visual> </xacro:unless>
    <xacro:unless value="${disable_mesh}"> <collision>
      <origin xyz="0 0 0" rpy="0 -0 0"/>
      <geometry>
        <mesh filename="package://seed_r7_description/meshes/typeG_otama_upperbody/elbow_middle_link.dae" scale="1 1 1" />
      </geometry>
    </collision> </xacro:unless>
    <inertial>
      <mass value="0.162" />
      <origin xyz="-0.014 0 -0.032" rpy="0 -0 0"/>
      <inertia ixx="0.00178" ixy="0" ixz="0" iyy="0.00179" iyz="0" izz="0.0035"/>
    </inertial>
  </link>
  <xacro:gazebo_link_reference link_name="l_elbow_middle_link" />

  <link name="l_elbow_link">
    <xacro:unless value="${disable_mesh}"> <visual>
      <origin xyz="0 0 0" rpy="0 -0 0"/>
      <geometry>
        <mesh filename="package://seed_r7_description/meshes/typeG_otama_upperbody/elbow_link.dae" scale="1 1 1" />
      </geometry>
    </visual> </xacro:unless>
    <xacro:unless value="${disable_mesh}"> <collision>
      <origin xyz="0 0 0" rpy="0 -0 0"/>
      <geometry>
        <mesh filename="package://seed_r7_description/meshes/typeG_otama_upperbody/elbow_link.dae" scale="1 1 1" />
      </geometry>
    </collision> </xacro:unless>
    <inertial>
      <mass value="0.711" />
      <!--origin xyz="0.0047 0 -0.0546" rpy="0 -0 0"/>
      <inertia ixx="0.00178" ixy="0" ixz="0" iyy="0.00179" iyz="0" izz="0.000273"/-->
      <!-- fix for gazebo -->
      <origin xyz="-0.03 0 -0.0546" rpy="0 -0 0"/>
      <inertia ixx="0.00178" ixy="0" ixz="0" iyy="0.00179" iyz="0" izz="0.0035"/>
    </inertial>
  </link>
  <xacro:gazebo_link_reference link_name="l_elbow_link" />

  <link name="l_forearm_link">
    <xacro:unless value="${disable_mesh}"> <visual>
      <origin xyz="0 0 0" rpy="0 0 0"/>
      <geometry>
        <mesh filename="package://seed_r7_description/meshes/typeG_otama_upperbody/l_forearm_link.dae" scale="1 1 1" />
      </geometry>
    </visual> </xacro:unless>
    <xacro:unless value="${disable_mesh}"> <collision>
      <origin xyz="0 0 0" rpy="0 0 0"/>
      <geometry>
        <mesh filename="package://seed_r7_description/meshes/typeG_otama_upperbody/l_forearm_link.dae" scale="1 1 1" />
      </geometry>
    </collision> </xacro:unless>
    <inertial>
      <mass value="0.132" />
      <origin xyz="0.006 0 -0.0738" rpy="0 -0 0"/>
      <!--inertia ixx="0.00276" ixy="0" ixz="0" iyy="0.00286" iyz="0" izz="0.004"/-->
      <inertia ixx="0.0007" ixy="0" ixz="0" iyy="0.0007" iyz="0" izz="0.0004"/>
    </inertial>
  </link>
  <xacro:gazebo_link_reference link_name="l_forearm_link" />

  <link name="l_wrist_center">
    <xacro:unless value="${disable_mesh}"> <visual>
      <origin xyz="0 0 0" rpy="0 0 0"/>
      <geometry>
        <mesh filename="package://seed_r7_description/meshes/typeG_otama_upperbody/l_wrist_center_link.dae" scale="1 1 1" />
      </geometry>
    </visual> </xacro:unless>
    <xacro:unless value="${disable_mesh}"> <collision>
      <origin xyz="0 0 0" rpy="0 0 0"/>
      <geometry>
        <mesh filename="package://seed_r7_description/meshes/typeG_otama_upperbody/l_wrist_center_link.dae" scale="1 1 1" />
      </geometry>
    </collision> </xacro:unless>
    <inertial>
      <mass value="0.05" />
      <origin xyz="0 0 0" rpy="0 -0 0"/>
      <inertia ixx="0.0001" ixy="0" ixz="0" iyy="0.0001" iyz="0" izz="0.0001"/>
    </inertial>
  </link>
  <xacro:gazebo_link_reference link_name="l_wrist_center" />

  <link name="l_wrist_r_link">
    <xacro:unless value="${disable_mesh}"> <visual>
      <origin xyz="0 0 0" rpy="0 0 0"/>
      <geometry>
        <mesh filename="package://seed_r7_description/meshes/typeG_otama_upperbody/l_wrist_r_link.dae" scale="1 1 1" />
      </geometry>
    </visual> </xacro:unless>
    <xacro:unless value="${disable_mesh}"> <collision>
      <origin xyz="0 0 0" rpy="0 0 0"/>
      <geometry>
        <mesh filename="package://seed_r7_description/meshes/typeG_otama_upperbody/l_wrist_r_link.dae" scale="1 1 1" />
      </geometry>
    </collision> </xacro:unless>
    <inertial>
      <mass value="0.05" />
      <origin xyz="0 0 0" rpy="0 -0 0"/>
      <inertia ixx="0.0001" ixy="0" ixz="0" iyy="0.0001" iyz="0" izz="0.0001"/>
    </inertial>
  </link>
  <xacro:gazebo_link_reference link_name="l_wrist_r_link" />

  <link name="neck_link">
    <xacro:unless value="${disable_mesh}"> <visual>
      <origin xyz="0 0 0" rpy="0 -0 0"/>
      <geometry>
        <mesh filename="package://seed_r7_description/meshes/typeG_otama_upperbody/neck_link.dae" scale="1 1 1" />
      </geometry>
    </visual> </xacro:unless>
    <xacro:unless value="${disable_mesh}"> <collision>
      <origin xyz="0 0 0" rpy="0 -0 0"/>
      <geometry>
        <mesh filename="package://seed_r7_description/meshes/typeG_otama_upperbody/neck_link.dae" scale="1 1 1" />
      </geometry>
    </collision> </xacro:unless>
    <inertial>
      <mass value="0.341" />
      <origin xyz="0 0 0.0595" rpy="0 -0 0"/>
      <!--inertia ixx="1.64186e-35" ixy="0" ixz="0" iyy="1.64186e-35" iyz="0" izz="0"/-->
      <inertia ixx="0.001" ixy="0" ixz="0" iyy="0.001" iyz="0" izz="0.002"/>
    </inertial>
  </link>
  <xacro:gazebo_link_reference link_name="neck_link" />

  <link name="head_base_link">
    <xacro:unless value="${disable_mesh}"> <visual>
      <origin xyz="0 0 0" rpy="0 -0 0"/>
      <geometry>
        <mesh filename="package://seed_r7_description/meshes/typeG_otama_upperbody/head_base_link.dae" scale="1 1 1" />
      </geometry>
    </visual> </xacro:unless>
    <xacro:unless value="${disable_mesh}"> <collision>
      <origin xyz="0 0 0" rpy="0 -0 0"/>
      <geometry>
        <mesh filename="package://seed_r7_description/meshes/typeG_otama_upperbody/head_base_link.dae" scale="1 1 1" />
      </geometry>
    </collision> </xacro:unless>
    <inertial>
      <mass value="0.1" />
      <origin xyz="0 0 0" rpy="0 -0 0"/>
      <inertia ixx="0.0005" ixy="0" ixz="0" iyy="0.0005" iyz="0" izz="0.0005"/>
    </inertial>
  </link>
  <xacro:gazebo_link_reference link_name="head_base_link" />

  <link name="head_link">
    <xacro:unless value="${disable_mesh}"> <visual>
      <origin xyz="0 0 0" rpy="0 -0 0"/>
      <geometry>
        <mesh filename="package://seed_r7_description/meshes/typeG_otama_upperbody/head_link.dae" scale="1 1 1" />
      </geometry>
    </visual> </xacro:unless>
    <xacro:unless value="${disable_mesh}"> <collision>
      <origin xyz="0 0 0" rpy="0 -0 0"/>
      <geometry>
        <mesh filename="package://seed_r7_description/meshes/typeG_otama_upperbody/head_link.dae" scale="1 1 1" />
      </geometry>
    </collision> </xacro:unless>
    <inertial>
      <mass value="0.974" />
      <origin xyz="0.01 0 0.070" rpy="0 -0 0"/>
      <inertia ixx="0.005" ixy="0" ixz="0" iyy="0.005" iyz="0" izz="0.005"/>
    </inertial>
  </link>
  <xacro:gazebo_link_reference link_name="head_link" />

  <link name="r_shoulder_link">
    <xacro:unless value="${disable_mesh}"> <visual>
      <origin xyz="0 0 0" rpy="0 0 0"/>
      <geometry>
        <mesh filename="package://seed_r7_description/meshes/typeG_otama_upperbody/r_shoulder_link.dae" scale="1 1 1" />
      </geometry>
    </visual> </xacro:unless>
    <xacro:unless value="${disable_mesh}"> <collision>
      <origin xyz="0 0 0" rpy="0 0 0"/>
      <geometry>
        <mesh filename="package://seed_r7_description/meshes/typeG_otama_upperbody/r_shoulder_link.dae" scale="1 1 1" />
      </geometry>
    </collision> </xacro:unless>
    <inertial>
      <mass value="0.242" />
      <!--origin xyz="0 -0.02 0" rpy="0 -0 0"/>
      <inertia ixx="0.000228" ixy="0" ixz="0" iyy="0.000148" iyz="0" izz="0.000263"/-->
      <origin xyz="0 -0.02 0.015" rpy="0 -0 0"/>
      <inertia ixx="0.00133" ixy="0" ixz="0" iyy="0.001" iyz="0" izz="0.00133"/>
    </inertial>
  </link>
  <xacro:gazebo_link_reference link_name="r_shoulder_link" />

  <link name="r_shoulder_center">
    <xacro:unless value="${disable_mesh}"> <visual>
      <origin xyz="0 0 0" rpy="0 -0 0"/>
      <geometry>
        <mesh filename="package://seed_r7_description/meshes/typeG_otama_upperbody/r_shoulder_center_link.dae" scale="1 1 1" />
      </geometry>
    </visual> </xacro:unless>
    <xacro:unless value="${disable_mesh}"> <collision>
      <origin xyz="0 0 0" rpy="0 -0 0"/>
      <geometry>
        <mesh filename="package://seed_r7_description/meshes/typeG_otama_upperbody/r_shoulder_center_link.dae" scale="1 1 1" />
      </geometry>
    </collision> </xacro:unless>
    <inertial>
      <mass value="0.744" />
      <!--origin xyz="0 -0.01 0" rpy="0 -0 0"/-->
      <origin xyz="0 0.01 -0.06" rpy="0 -0 0"/>
      <inertia ixx="0.000841" ixy="0" ixz="0" iyy="0.000835" iyz="0" izz="0.000305"/>
    </inertial>
  </link>
  <xacro:gazebo_link_reference link_name="r_shoulder_center" />

  <link name="r_upperarm_link">
    <xacro:unless value="${disable_mesh}"> <visual>
      <origin xyz="0 0 0" rpy="0 -0 0"/>
      <geometry>
        <mesh filename="package://seed_r7_description/meshes/typeG_otama_upperbody/upperarm_link.dae" scale="1 1 1" />
      </geometry>
    </visual> </xacro:unless>
    <xacro:unless value="${disable_mesh}"> <collision>
      <origin xyz="0 0 0" rpy="0 -0 0"/>
      <geometry>
        <mesh filename="package://seed_r7_description/meshes/typeG_otama_upperbody/upperarm_link.dae" scale="1 1 1" />
      </geometry>
    </collision> </xacro:unless>
    <inertial>
      <mass value="0.574" />
      <!--origin xyz="0.005 0 -0.0654" rpy="0 -0 0"/>
      <inertia ixx="0.00114" ixy="0" ixz="0" iyy="0.00117" iyz="0" izz="0.000269"/-->
      <!-- fix for gazebo -->
      <origin xyz="0.005 0 -0.0654" rpy="0 -0 0"/>
      <inertia ixx="0.00214" ixy="0" ixz="0" iyy="0.00217" iyz="0" izz="0.003"/>
    </inertial>
  </link>
  <xacro:gazebo_link_reference link_name="r_upperarm_link" />

  <link name="r_elbow_virtual_link">
    <inertial>
      <mass value="0.001" />
      <origin xyz="0 0 0" rpy="0 0 0"/>
      <inertia ixx="0.01" ixy="0" ixz="0" iyy="0.01" iyz="0" izz="0.01"/>
    </inertial>
  </link>
  <xacro:gazebo_link_reference link_name="r_elbow_virtual_link" />

  <link name="r_elbow_virtual_link_dummy">
    <inertial>
      <mass value="0.001" />
      <origin xyz="0 0 0" rpy="0 0 0"/>
      <inertia ixx="0.01" ixy="0" ixz="0" iyy="0.01" iyz="0" izz="0.01"/>
    </inertial>
  </link>
  <xacro:gazebo_link_reference link_name="r_elbow_virtual_link_dummy" />

  <link name="r_elbow_middle_link">
    <xacro:unless value="${disable_mesh}"> <visual>
      <origin xyz="0 0 0" rpy="0 -0 0"/>
      <geometry>
        <mesh filename="package://seed_r7_description/meshes/typeG_otama_upperbody/elbow_middle_link.dae" scale="1 1 1" />
      </geometry>
    </visual> </xacro:unless>
    <xacro:unless value="${disable_mesh}"> <collision>
      <origin xyz="0 0 0" rpy="0 -0 0"/>
      <geometry>
        <mesh filename="package://seed_r7_description/meshes/typeG_otama_upperbody/elbow_middle_link.dae" scale="1 1 1" />
      </geometry>
    </collision> </xacro:unless>
    <inertial>
      <mass value="0.162" />
      <origin xyz="-0.014 0 -0.032" rpy="0 -0 0"/>
      <inertia ixx="0.00178" ixy="0" ixz="0" iyy="0.00179" iyz="0" izz="0.0035"/>
    </inertial>
  </link>
  <xacro:gazebo_link_reference link_name="r_elbow_middle_link" />

  <link name="r_elbow_link">
    <xacro:unless value="${disable_mesh}"> <visual>
      <origin xyz="0 0 0" rpy="0 -0 0"/>
      <geometry>
        <mesh filename="package://seed_r7_description/meshes/typeG_otama_upperbody/elbow_link.dae" scale="1 1 1" />
      </geometry>
    </visual> </xacro:unless>
    <xacro:unless value="${disable_mesh}"> <collision>
      <origin xyz="0 0 0" rpy="0 -0 0"/>
      <geometry>
        <mesh filename="package://seed_r7_description/meshes/typeG_otama_upperbody/elbow_link.dae" scale="1 1 1" />
      </geometry>
    </collision> </xacro:unless>
    <inertial>
      <mass value="0.711" />
      <!--origin xyz="0.0047 0 -0.0546" rpy="0 -0 0"/>
      <inertia ixx="0.00178" ixy="0" ixz="0" iyy="0.00179" iyz="0" izz="0.000273"/-->
      <!-- fix for gazebo -->
      <origin xyz="-0.03 0 -0.0546" rpy="0 -0 0"/>
      <inertia ixx="0.00178" ixy="0" ixz="0" iyy="0.00179" iyz="0" izz="0.0035"/>
    </inertial>
  </link>
  <xacro:gazebo_link_reference link_name="r_elbow_link" />

  <link name="r_forearm_link">
    <xacro:unless value="${disable_mesh}"> <visual>
      <origin xyz="0 0 0" rpy="0 0 0"/>
      <geometry>
        <mesh filename="package://seed_r7_description/meshes/typeG_otama_upperbody/r_forearm_link.dae" scale="1 1 1" />
      </geometry>
    </visual> </xacro:unless>
    <xacro:unless value="${disable_mesh}"> <collision>
      <origin xyz="0 0 0" rpy="0 0 0"/>
      <geometry>
        <mesh filename="package://seed_r7_description/meshes/typeG_otama_upperbody/r_forearm_link.dae" scale="1 1 1" />
      </geometry>
    </collision> </xacro:unless>
    <inertial>
      <mass value="0.132" />
      <origin xyz="0.006 0 -0.0738" rpy="0 -0 0"/>
      <!--inertia ixx="0.00276" ixy="0" ixz="0" iyy="0.00286" iyz="0" izz="0.004"/-->
      <inertia ixx="0.0007" ixy="0" ixz="0" iyy="0.0007" iyz="0" izz="0.0004"/>
    </inertial>
  </link>
  <xacro:gazebo_link_reference link_name="r_forearm_link" />

  <link name="r_wrist_center">
    <xacro:unless value="${disable_mesh}"> <visual>
      <origin xyz="0 0 0" rpy="0 0 0"/>
      <geometry>
        <mesh filename="package://seed_r7_description/meshes/typeG_otama_upperbody/r_wrist_center_link.dae" scale="1 1 1" />
      </geometry>
    </visual> </xacro:unless>
    <xacro:unless value="${disable_mesh}"> <collision>
      <origin xyz="0 0 0" rpy="0 0 0"/>
      <geometry>
        <mesh filename="package://seed_r7_description/meshes/typeG_otama_upperbody/r_wrist_center_link.dae" scale="1 1 1" />
      </geometry>
    </collision> </xacro:unless>
    <inertial>
      <mass value="0.05" />
      <origin xyz="0 0 0" rpy="0 -0 0"/>
      <inertia ixx="0.0001" ixy="0" ixz="0" iyy="0.0001" iyz="0" izz="0.0001"/>
    </inertial>
  </link>
  <xacro:gazebo_link_reference link_name="r_wrist_center" />

  <link name="r_wrist_r_link">
    <xacro:unless value="${disable_mesh}"> <visual>
      <origin xyz="0 0 0" rpy="0 0 0"/>
      <geometry>
        <mesh filename="package://seed_r7_description/meshes/typeG_otama_upperbody/r_wrist_r_link.dae" scale="1 1 1" />
      </geometry>
    </visual> </xacro:unless>
    <xacro:unless value="${disable_mesh}"> <collision>
      <origin xyz="0 0 0" rpy="0 0 0"/>
      <geometry>
        <mesh filename="package://seed_r7_description/meshes/typeG_otama_upperbody/r_wrist_r_link.dae" scale="1 1 1" />
      </geometry>
    </collision> </xacro:unless>
    <inertial>
      <mass value="0.05" />
      <origin xyz="0 0 0" rpy="0 -0 0"/>
      <inertia ixx="0.0001" ixy="0" ixz="0" iyy="0.0001" iyz="0" izz="0.0001"/>
    </inertial>
  </link>
  <xacro:gazebo_link_reference link_name="r_wrist_r_link" />

  <joint name="waist_y_joint" type="revolute">
    <parent link="${base_link}"/>
    <child  link="hip_sphere_link"/>
    <origin xyz="0 0 0.005" rpy="0 -0 0 "/>
    <axis   xyz="0 0 1"/>
    <!-- from -120 to 120 degrees-->
    <limit lower="-2.09" upper="2.09" effort="500" velocity="0.6" />
    <dynamics damping="0.2" friction="0" />
  </joint>
  <xacro:gazebo_transmission joint_name="waist_y_joint" />

  <joint name="waist_p_joint" type="revolute">
    <parent link="hip_sphere_link"/>
    <child  link="hip_center"/>
    <origin xyz="0 0 0.132" rpy="0 -0 0 "/>
    <axis   xyz="0 1 0"/>
    <!-- from -10 to 40 degrees-->
    <limit lower="-0.17" upper="0.69" effort="500" velocity="0.4" />
    <dynamics damping="0.2" friction="0" />
  </joint>
  <xacro:gazebo_transmission joint_name="waist_p_joint" />

  <joint name="waist_r_joint" type="revolute">
    <parent link="hip_center"/>
    <child  link="body_link"/>
    <origin xyz="0 0 0" rpy="0 -0 0 "/>
    <axis   xyz="1 0 0"/>
    <!-- from -7 to 7 degrees-->
    <limit lower="-0.12" upper="0.12" effort="500" velocity="0.3" />
    <dynamics damping="0.2" friction="0" />
  </joint>
  <xacro:gazebo_transmission joint_name="waist_r_joint" />

  <joint name="l_shoulder_p_joint" type="revolute">
    <parent link="body_link"/>
    <child  link="l_shoulder_link"/>
    <origin xyz="-0.018 0.134202 0.251871" rpy="0 0 0 "/>
    <axis   xyz="0 0.984808 -0.173648"/>
    <!-- from -89 to 17 degrees-->
    <limit lower="-1.55" upper="0.29" effort="200" velocity="0.4" />
    <dynamics damping="0.2" friction="0" />
  </joint>
  <xacro:gazebo_transmission joint_name="l_shoulder_p_joint" />

  <joint name="l_shoulder_r_joint" type="revolute">
    <parent link="l_shoulder_link"/>
    <child  link="l_shoulder_center"/>
    <origin xyz="0 0.064702 0.027177" rpy="0 0 0 "/>
    <axis   xyz="1 0 0"/>
    <!-- from -5 to 90 degrees-->
    <limit lower="-0.08" upper="1.57" effort="100" velocity="0.5" />
    <dynamics damping="0.2" friction="0" />
  </joint>
  <xacro:gazebo_transmission joint_name="l_shoulder_r_joint" />

  <joint name="l_shoulder_y_joint" type="revolute">
    <parent link="l_shoulder_center"/>
    <child  link="l_upperarm_link"/>
    <origin xyz="0 -0.01 -0.0455" rpy="0 -0 0 "/>
    <axis   xyz="0 0 1"/>
    <!-- from -90 to 90 degrees-->
    <limit lower="-1.57" upper="1.57" effort="100" velocity="1.1" />
    <dynamics damping="0.2" friction="0" />
  </joint>
  <xacro:gazebo_transmission joint_name="l_shoulder_y_joint" />

  <joint name="l_wrist_y_joint" type="revolute">
    <parent link="l_elbow_link"/>
    <child  link="l_forearm_link"/>
    <origin xyz="0.0 0 -0.1095" rpy="0 -0 0 "/>
    <axis   xyz="0 0 1"/>
    <!-- from -135 to 135 degrees-->
    <limit lower="-2.35" upper="2.35" effort="100" velocity="1.2" />
    <dynamics damping="0.2" friction="0" />
  </joint>
  <xacro:gazebo_transmission joint_name="l_wrist_y_joint" />

  <joint name="l_wrist_p_joint" type="revolute">
    <parent link="l_forearm_link"/>
    <child  link="l_wrist_center"/>
    <origin xyz="0 0 -0.124" rpy="0 -0 0 "/>
    <axis   xyz="0 1 0"/>
    <!-- from -20 to 20 degrees-->
    <limit lower="-0.34" upper="0.34" effort="100" velocity="0.8" />
    <dynamics damping="0.2" friction="0" />
  </joint>
  <xacro:gazebo_transmission joint_name="l_wrist_p_joint" />

  <joint name="l_wrist_r_joint" type="revolute">
    <parent link="l_wrist_center"/>
    <child  link="l_wrist_r_link"/>
    <origin xyz="0 0 0" rpy="0 -0 0 "/>
    <axis   xyz="1 0 0"/>
    <!-- from -90 to 20 degrees-->
    <limit lower="-1.57" upper="0.34" effort="100" velocity="1.8" />
    <dynamics damping="0.2" friction="0" />
  </joint>
  <xacro:gazebo_transmission joint_name="l_wrist_r_joint" />

  <joint name="l_wrist_to_hand_connector" type="fixed">
    <parent link="l_wrist_r_link"/>
    <child  link="${l_hand_link}"/>
    <origin xyz="0 0 -0.003" rpy="0 0 0 "/>
  </joint>
  <!-- <xacro:gazebo_transmission joint_name="l_wrist_to_hand_connector" /> -->

  <joint name="neck_y_joint" type="revolute">
    <parent link="body_link"/>
    <child  link="neck_link"/>
    <origin xyz="0.002 0 0.377" rpy="0 -0 0 "/>
    <axis   xyz="0 0 1"/>
    <!-- from -120 to 120 degrees-->
    <limit lower="-2.09" upper="2.09" effort="100" velocity="1.7" />
    <dynamics damping="0.2" friction="0" />
  </joint>
  <xacro:gazebo_transmission joint_name="neck_y_joint" />

  <joint name="neck_p_joint" type="revolute">
    <parent link="neck_link"/>
    <child  link="head_base_link"/>
    <!-- real x=0.015 but can't move by eef of head, so set below-->
    <origin xyz="0.0 0 0.0265" rpy="0 -0 0 "/>
    <axis   xyz="0 1 0"/>
    <!-- from -20 to 30 degrees-->
    <limit lower="-0.34" upper="0.52" effort="100" velocity="2.1" />
    <dynamics damping="0.2" friction="0" />
  </joint>
  <xacro:gazebo_transmission joint_name="neck_p_joint" />

  <joint name="neck_r_joint" type="revolute">
    <parent link="head_base_link"/>
    <child  link="head_link"/>
    <origin xyz="0 0 0" rpy="0 -0 0 "/>
    <axis   xyz="1 0 0"/>
    <!-- from -20 to 20 degrees-->
    <limit lower="-0.34" upper="0.34" effort="100" velocity="0.8" />
    <dynamics damping="0.2" friction="0" />
  </joint>
  <xacro:gazebo_transmission joint_name="neck_r_joint" />

  <joint name="r_shoulder_p_joint" type="revolute">
    <parent link="body_link"/>
    <child  link="r_shoulder_link"/>
    <origin xyz="-0.018 -0.134202 0.251871" rpy="0 -0 0 "/>
    <axis   xyz="0 0.984808 0.173648"/>
    <!-- from -89 to 17 degrees-->
    <limit lower="-1.55" upper="0.29" effort="200" velocity="0.4" />
    <dynamics damping="0.2" friction="0" />
  </joint>
  <xacro:gazebo_transmission joint_name="r_shoulder_p_joint" />

  <joint name="r_shoulder_r_joint" type="revolute">
    <parent link="r_shoulder_link"/>
    <child  link="r_shoulder_center"/>
    <origin xyz="0 -0.064702 0.027177" rpy="0 -0 0 "/>
    <axis   xyz="1 0 0"/>
    <!-- from -90 to 5 degrees-->
    <limit lower="-1.57" upper="0.08" effort="100" velocity="0.5" />
    <dynamics damping="0.2" friction="0" />
  </joint>
  <xacro:gazebo_transmission joint_name="r_shoulder_r_joint" />

  <joint name="r_shoulder_y_joint" type="revolute">
    <parent link="r_shoulder_center"/>
    <child  link="r_upperarm_link"/>
    <origin xyz="0 0.01 -0.0455" rpy="0 -0 0 "/>
    <axis   xyz="0 0 1"/>
    <!-- from -180 to 180 degrees-->
    <limit lower="-1.57" upper="1.57" effort="100" velocity="1.1" />
    <dynamics damping="0.2" friction="0" />
  </joint>
  <xacro:gazebo_transmission joint_name="r_shoulder_y_joint" />

  <joint name="r_wrist_y_joint" type="revolute">
    <parent link="r_elbow_link"/>
    <child  link="r_forearm_link"/>
    <origin xyz="0.0 0 -0.1095" rpy="0 -0 0 "/>
    <axis   xyz="0 0 1"/>
    <!-- from -135 to 135 degrees-->
    <limit lower="-2.35" upper="2.35" effort="100" velocity="1.2" />
    <dynamics damping="0.2" friction="0" />
  </joint>
  <xacro:gazebo_transmission joint_name="r_wrist_y_joint" />

  <joint name="r_wrist_p_joint" type="revolute">
    <parent link="r_forearm_link"/>
    <child  link="r_wrist_center"/>
    <origin xyz="0 0 -0.124" rpy="0 -0 0 "/>
    <axis   xyz="0 1 0"/>
    <!-- from -20 to 20 degrees-->
    <limit lower="-0.34" upper="0.34" effort="100" velocity="0.8" />
    <dynamics damping="0.2" friction="0" />
  </joint>
  <xacro:gazebo_transmission joint_name="r_wrist_p_joint" />

  <joint name="r_wrist_r_joint" type="revolute">
    <parent link="r_wrist_center"/>
    <child  link="r_wrist_r_link"/>
    <origin xyz="0 0 0" rpy="0 -0 0 "/>
    <axis   xyz="1 0 0"/>
    <!-- from -20 to 90 degrees-->
    <limit lower="-0.34" upper="1.57" effort="100" velocity="1.8" />
    <dynamics damping="0.2" friction="0" />
  </joint>
  <xacro:gazebo_transmission joint_name="r_wrist_r_joint" />

  <joint name="r_wrist_to_hand_connector" type="fixed">
    <parent link="r_wrist_r_link"/>
    <child  link="${r_hand_link}"/>
    <origin xyz="0 0 -0.003" rpy="0 0 0 "/>
  </joint>
  <!-- <xacro:gazebo_transmission joint_name="r_wrist_to_hand_connector" /> -->

  <joint name="r_elbow_joint" type="revolute">
    <parent link="r_upperarm_link"/>
    <child  link="r_elbow_virtual_link"/>
    <origin xyz="0.0 0 -0.2085" rpy="0 -0 0 "/>
    <axis   xyz="0 1 0"/>
    <!-- from -170 to 0 degrees-->
    <limit lower="-3.0" upper="0" effort="100" velocity="1.1" />
    <dynamics damping="0.2" friction="0.1" />
  </joint>
  <xacro:gazebo_transmission joint_name="r_elbow_joint" />

  <joint name="r_elbow_joint_mimic" type="continuous">
    <parent link="r_elbow_virtual_link"/>
    <child  link="r_elbow_virtual_link_dummy"/>
    <origin xyz="0.0 0 0" rpy="0 0 0 "/>
    <axis   xyz="0 1 0"/>
    <mimic joint="r_elbow_joint" multiplier="-1" offset="0" />
  </joint>

  <joint name="r_elbow_middle_joint" type="continuous">
    <parent link="r_elbow_virtual_link_dummy"/>
    <child  link="r_elbow_middle_link"/>
    <origin xyz="0.0 0 0" rpy="0 -0 0 "/>
    <axis   xyz="0 1 0"/>
    <mimic joint="r_elbow_joint" multiplier="0.591222" offset="0" />
  </joint>

  <joint name="r_elbow_middle_joint_mimic" type="continuous">
    <parent link="r_elbow_middle_link"/>
    <child  link="r_elbow_link"/>
    <origin xyz="0.0 0 -0.07" rpy="0 -0 0 "/>
    <axis   xyz="0 1 0"/>
    <mimic joint="r_elbow_joint" multiplier="0.408778" offset="0" />
  </joint>

  <joint name="l_elbow_joint" type="revolute">
    <parent link="l_upperarm_link"/>
    <child  link="l_elbow_virtual_link"/>
    <origin xyz="0.0 0 -0.2085" rpy="0 -0 0 "/>
    <axis   xyz="0 1 0"/>
    <!-- from -170 to 0 degrees-->
    <limit lower="-3.0" upper="0" effort="100" velocity="1.1" />
    <dynamics damping="0.2" friction="0.1" />
  </joint>
  <xacro:gazebo_transmission joint_name="l_elbow_joint" />

  <joint name="l_elbow_joint_mimic" type="continuous">
    <parent link="l_elbow_virtual_link"/>
    <child  link="l_elbow_virtual_link_dummy"/>
    <origin xyz="0.0 0 0" rpy="0 0 0 "/>
    <axis   xyz="0 1 0"/>
    <mimic joint="l_elbow_joint" multiplier="-1" offset="0" />
  </joint>

  <joint name="l_elbow_middle_joint" type="continuous">
    <parent link="l_elbow_virtual_link_dummy"/>
    <child  link="l_elbow_middle_link"/>
    <origin xyz="0.0 0 0" rpy="0 -0 0 "/>
    <axis   xyz="0 1 0"/>
    <mimic joint="l_elbow_joint" multiplier="0.591222" offset="0" />
  </joint>

  <joint name="l_elbow_middle_joint_mimic" type="continuous">
    <parent link="l_elbow_middle_link"/>
    <child  link="l_elbow_link"/>
    <origin xyz="0.0 0 -0.07" rpy="0 -0 0 "/>
    <axis   xyz="0 1 0"/>
    <mimic joint="l_elbow_joint" multiplier="0.408778" offset="0" />
  </joint>

  <link name="chest_camera_link"/>
  <joint name="body_link_to_chest_camera_link" type="fixed">
    <parent  link="body_link"/>
    <child link="chest_camera_link"/>
    <origin xyz="0.058198 0.0 0.273087" rpy="0 0.698132 0"/>
  </joint>

  <link name="chest_camera_right_ir_frame"/>
  <joint name="chest_camera_link_to_chest_camera_right_ir_link" type="fixed">
    <parent  link="chest_camera_link"/>
    <child link="chest_camera_right_ir_frame"/>
    <origin xyz="0 -0.055 0" rpy="0 0 0"/>  <!-- realsense d415-->
  </joint>

  </xacro:macro>
</robot>
