<?xml version="1.0"?>

<!-- XML namespaces -->
<robot name="noid_upper_typef" xmlns:xacro="http://ros.org/wiki/xacro">

  <xacro:include filename="$(find seed_r7_description)/urdf/gazebo.xacro" />

  <xacro:property name="wrist_sensor_offset" value="0.0"/>

  <xacro:macro name="noid_upper" params="base_link disable_mesh:=false r_hand_link:=r_hand_link l_hand_link:=l_hand_link">
  <!-- ============================   typeF_upper   ============================ -->
  <link name="${base_link}">
    <inertial>
      <mass value="1.257" />
      <origin xyz="0 0 0.0" rpy="0 -0 0"/>
      <inertia ixx="0.034" ixy="0" ixz="0" iyy="0.034" iyz="0" izz="0.018"/>
    </inertial>
  </link>
  <xacro:gazebo_link_reference link_name="${base_link}" />

  <link name="hip_sphere_link">
    <xacro:unless value="${disable_mesh}"> <visual>
      <origin xyz="0 0 0" rpy="0 -0 0"/>
      <geometry>
        <mesh filename="package://seed_r7_description/meshes/typeF_upperbody/WAIST_LINK1_mesh.dae" scale="1 1 1" />
      </geometry>
    </visual> </xacro:unless>
    <xacro:unless value="${disable_mesh}"> <collision>
<!--
      <origin xyz="0 0 0" rpy="0 -0 0"/>
      <geometry>
        <mesh filename="package://seed_r7_description/meshes/typeF_upperbody/WAIST_LINK1_mesh.dae" scale="1 1 1" />
      </geometry>
 -->
      <origin  xyz="0 0 0.04" rpy="0 0 0"/>
      <geometry>
        <cylinder length="0.09" radius="0.06"/>
      </geometry>
    </collision>
    <collision>
      <origin  xyz="0 0 0.12" rpy="0 0 0"/>
      <geometry>
        <sphere radius="0.078"/>
      </geometry>
    </collision> </xacro:unless>
    <inertial>
      <mass value="1.257" />
      <origin xyz="0 0 0.042" rpy="0 -0 0"/>
      <inertia ixx="0.01" ixy="0" ixz="0" iyy="0.01" iyz="0" izz="0.007"/>
    </inertial>
  </link>
  <xacro:gazebo_link_reference link_name="hip_sphere_link" />

  <link name="hip_center">
    <inertial>
      <mass value="0.1" />
      <origin xyz="0 0 0" rpy="0 -0 0"/>
      <inertia ixx="0.003" ixy="0" ixz="0" iyy="0.003" iyz="0" izz="0.003"/>
    </inertial>
  </link>
  <xacro:gazebo_link_reference link_name="hip_center" />

  <link name="body_link">
    <xacro:unless value="${disable_mesh}"> <visual>
      <origin xyz="0 0 0" rpy="0 -0 0"/>
      <geometry>
        <mesh filename="package://seed_r7_description/meshes/typeF_upperbody/WAIST_LINK3_mesh.dae" scale="1 1 1" />
      </geometry>
    </visual> </xacro:unless>
    <xacro:unless value="${disable_mesh}"> <collision>
      <origin xyz="0 0 0" rpy="0 -0 0"/>
      <geometry>
        <mesh filename="package://seed_r7_description/meshes/typeF_upperbody/WAIST_LINK3_mesh.dae" scale="1 1 1" />
      </geometry>
    </collision> </xacro:unless>
    <inertial>
      <mass value="10.551" />
      <origin xyz="0 0 0.22" rpy="0 -0 0"/>
      <inertia ixx="0.13" ixy="0" ixz="0" iyy="0.12" iyz="0" izz="0.114"/>
    </inertial>
  </link>
  <xacro:gazebo_link_reference link_name="body_link" />

  <link name="l_shoulder_link">
    <xacro:unless value="${disable_mesh}"> <visual>
      <origin xyz="0 0 0" rpy="-0.174532925 -0 0"/>
      <geometry>
        <mesh filename="package://seed_r7_description/meshes/typeF_upperbody/LARM_LINK1_mesh.dae" scale="1 1 1" />
      </geometry>
    </visual> </xacro:unless>
    <xacro:unless value="${disable_mesh}"> <collision>
      <origin xyz="0 0 0" rpy="-0.174532925 -0 0"/>
      <geometry>
        <mesh filename="package://seed_r7_description/meshes/typeF_upperbody/LARM_LINK1_mesh.dae" scale="1 1 1" />
      </geometry>
    </collision> </xacro:unless>
    <inertial>
      <mass value="0.242" />
      <origin xyz="0 0.02 0.015" rpy="0 -0 0"/>
      <inertia ixx="0.00133" ixy="0" ixz="0" iyy="0.001" iyz="0" izz="0.00133"/>
    </inertial>
  </link>
  <xacro:gazebo_link_reference link_name="l_shoulder_link" />

  <link name="l_shoulder_center">
    <xacro:unless value="${disable_mesh}"> <visual>
      <origin xyz="0 0 0" rpy="0 -0 0"/>
      <geometry>
        <mesh filename="package://seed_r7_description/meshes/typeF_upperbody/LARM_LINK2_mesh.dae" scale="1 1 1" />
      </geometry>
    </visual> </xacro:unless>
    <xacro:unless value="${disable_mesh}"> <collision>
      <origin xyz="0 0 0" rpy="0 -0 0"/>
      <geometry>
        <mesh filename="package://seed_r7_description/meshes/typeF_upperbody/LARM_LINK2_mesh.dae" scale="1 1 1" />
      </geometry>
    </collision> </xacro:unless>
    <inertial>
      <mass value="0.744" />
      <origin xyz="0 -0.01 -0.06" rpy="0 -0 0"/>
      <inertia ixx="0.000841" ixy="0" ixz="0" iyy="0.000835" iyz="0" izz="0.000304"/>
    </inertial>
  </link>
  <xacro:gazebo_link_reference link_name="l_shoulder_center" />

  <link name="l_upperarm_link">
    <xacro:unless value="${disable_mesh}"> <visual>
      <origin xyz="0 0 0" rpy="0 -0 0"/>
      <geometry>
        <mesh filename="package://seed_r7_description/meshes/typeF_upperbody/LARM_LINK3_mesh.dae" scale="1 1 1" />
      </geometry>
    </visual> </xacro:unless>
    <xacro:unless value="${disable_mesh}"> <collision>
<!--
      <origin xyz="0 0 0" rpy="0 -0 0"/>
      <geometry>
        <mesh filename="package://seed_r7_description/meshes/typeF_upperbody/LARM_LINK3_mesh.dae" scale="1 1 1" />
      </geometry>
 -->
      <origin  xyz="-0.005 0 -0.08" rpy="0 0 0"/>
      <geometry>
        <box size="0.076 0.065 0.18" />
      </geometry>
    </collision> </xacro:unless>
    <inertial>
      <mass value="0.574" />
      <origin xyz="0.005 0 -0.0654" rpy="0 -0 0"/>
      <inertia ixx="0.00214" ixy="0" ixz="0" iyy="0.00217" iyz="0" izz="0.003"/>
    </inertial>
  </link>
  <xacro:gazebo_link_reference link_name="l_upperarm_link" />

  <link name="l_elbow_link">
    <xacro:unless value="${disable_mesh}"> <visual>
      <origin xyz="-0.035 0 -0.035" rpy="0 -0 0"/>
      <geometry>
        <mesh filename="package://seed_r7_description/meshes/typeF_upperbody/LARM_LINK4_mesh.dae" scale="1 1 1" />
      </geometry>
    </visual> </xacro:unless>
    <xacro:unless value="${disable_mesh}"> <collision>
<!--
      <origin xyz="-0.035 0 -0.035" rpy="0 -0 0"/>
      <geometry>
        <mesh filename="package://seed_r7_description/meshes/typeF_upperbody/LARM_LINK4_mesh.dae" scale="1 1 1" />
      </geometry>
 -->
      <origin  xyz="-0.035 0 -0.03" rpy="0 0 0"/>
      <geometry>
        <box size="0.06 0.051 0.075" />
      </geometry>
    </collision> </xacro:unless>
    <inertial>
      <mass value="0.711" />
      <origin xyz="-0.03 0 -0.0546" rpy="0 -0 0"/>
      <inertia ixx="0.00178" ixy="0" ixz="0" iyy="0.00179" iyz="0" izz="0.0035"/>
    </inertial>
  </link>
  <xacro:gazebo_link_reference link_name="l_elbow_link" />

  <link name="l_forearm_link">
    <xacro:unless value="${disable_mesh}"> <visual>
      <origin xyz="0 0 0" rpy="0 0 -1.5707963267948966"/>
      <geometry>
        <mesh filename="package://seed_r7_description/meshes/typeF_upperbody/LARM_LINK5_mesh.dae" scale="1 1 1" />
      </geometry>
    </visual> </xacro:unless>
    <xacro:unless value="${disable_mesh}"> <collision>
      <origin xyz="0 0 0" rpy="0 0 -1.5707963267948966"/>
      <geometry>
        <mesh filename="package://seed_r7_description/meshes/typeF_upperbody/LARM_LINK5_mesh.dae" scale="1 1 1" />
      </geometry>
    </collision> </xacro:unless>
    <inertial>
      <mass value="0.132" />
      <origin xyz="0.006 0 -0.0738" rpy="0 -0 0"/>
      <inertia ixx="0.0007" ixy="0" ixz="0" iyy="0.0007" iyz="0" izz="0.0004"/>
    </inertial>
  </link>
  <xacro:gazebo_link_reference link_name="l_forearm_link" />

  <link name="l_wrist_center">
    <inertial>
      <mass value="0.05" />
      <origin xyz="0 0 0" rpy="0 -0 0"/>
      <inertia ixx="0.0001" ixy="0" ixz="0" iyy="0.0001" iyz="0" izz="0.0001"/>
    </inertial>
  </link>
  <xacro:gazebo_link_reference link_name="l_wrist_center" />

  <link name="neck_link">
    <xacro:unless value="${disable_mesh}"> <visual>
      <origin xyz="0 0 0" rpy="0 -0 0"/>
      <geometry>
        <mesh filename="package://seed_r7_description/meshes/typeF_upperbody/NECK_LINK1_mesh.dae" scale="1 1 1" />
      </geometry>
    </visual> </xacro:unless>
    <xacro:unless value="${disable_mesh}"> <collision>
      <origin xyz="0 0 0" rpy="0 -0 0"/>
      <geometry>
        <mesh filename="package://seed_r7_description/meshes/typeF_upperbody/NECK_LINK1_mesh.dae" scale="1 1 1" />
      </geometry>
    </collision> </xacro:unless>
    <inertial>
      <mass value="0.341" />
      <origin xyz="0 0 0.0595" rpy="0 -0 0"/>
      <inertia ixx="0.001" ixy="0" ixz="0" iyy="0.001" iyz="0" izz="0.002"/>
    </inertial>
  </link>
  <xacro:gazebo_link_reference link_name="neck_link" />

  <link name="head_base_link">
    <xacro:unless value="${disable_mesh}"> <visual>
      <origin xyz="0 0 0" rpy="0 -0 0"/>
      <geometry>
        <mesh filename="package://seed_r7_description/meshes/typeF_upperbody/NECK_LINK2_mesh.dae" scale="1 1 1" />
      </geometry>
    </visual> </xacro:unless>
    <xacro:unless value="${disable_mesh}"> <collision>
      <origin xyz="0 0 0" rpy="0 -0 0"/>
      <geometry>
        <mesh filename="package://seed_r7_description/meshes/typeF_upperbody/NECK_LINK2_mesh.dae" scale="1 1 1" />
      </geometry>
    </collision> </xacro:unless>
    <inertial>
      <mass value="0.1" />
      <origin xyz="0 0 0" rpy="0 -0 0"/>
      <inertia ixx="0.0005" ixy="0" ixz="0" iyy="0.0005" iyz="0" izz="0.0005"/>
    </inertial>
  </link>
  <xacro:gazebo_link_reference link_name="head_base_link" />

  <link name="head_link">
    <xacro:unless value="${disable_mesh}"> <visual>
      <origin xyz="0 0 0" rpy="0 -0 0"/>
      <geometry>
        <mesh filename="package://seed_r7_description/meshes/typeF_upperbody/NECK_LINK3_mesh.dae" scale="1 1 1" />
      </geometry>
    </visual> </xacro:unless>
    <xacro:unless value="${disable_mesh}"> <collision>
      <origin xyz="0 0 0" rpy="0 -0 0"/>
      <geometry>
        <mesh filename="package://seed_r7_description/meshes/typeF_upperbody/NECK_LINK3_mesh.dae" scale="1 1 1" />
      </geometry>
    </collision> </xacro:unless>
    <inertial>
      <mass value="0.974" />
      <origin xyz="0.01 0 0.070" rpy="0 -0 0"/>
      <inertia ixx="0.005" ixy="0" ixz="0" iyy="0.005" iyz="0" izz="0.005"/>
    </inertial>
  </link>
  <xacro:gazebo_link_reference link_name="head_link" />

  <link name="r_shoulder_link">
    <xacro:unless value="${disable_mesh}"> <visual>
      <origin xyz="0 0 0" rpy="0.174532925 -0 0"/>
      <geometry>
        <mesh filename="package://seed_r7_description/meshes/typeF_upperbody/RARM_LINK1_mesh.dae" scale="1 1 1" />
      </geometry>
    </visual> </xacro:unless>
    <xacro:unless value="${disable_mesh}"> <collision>
      <origin xyz="0 0 0" rpy="0.174532925 -0 0"/>
      <geometry>
        <mesh filename="package://seed_r7_description/meshes/typeF_upperbody/RARM_LINK1_mesh.dae" scale="1 1 1" />
      </geometry>
    </collision> </xacro:unless>
    <inertial>
      <mass value="0.242" />
      <origin xyz="0 -0.02 0.015" rpy="0 -0 0"/>
      <inertia ixx="0.00133" ixy="0" ixz="0" iyy="0.001" iyz="0" izz="0.00133"/>
    </inertial>
  </link>
  <xacro:gazebo_link_reference link_name="r_shoulder_link" />

  <link name="r_shoulder_center">
    <xacro:unless value="${disable_mesh}"> <visual>
      <origin xyz="0 0 0" rpy="0 -0 0"/>
      <geometry>
        <mesh filename="package://seed_r7_description/meshes/typeF_upperbody/RARM_LINK2_mesh.dae" scale="1 1 1" />
      </geometry>
    </visual> </xacro:unless>
    <xacro:unless value="${disable_mesh}"> <collision>
      <origin xyz="0 0 0" rpy="0 -0 0"/>
      <geometry>
        <mesh filename="package://seed_r7_description/meshes/typeF_upperbody/RARM_LINK2_mesh.dae" scale="1 1 1" />
      </geometry>
    </collision> </xacro:unless>
    <inertial>
      <mass value="0.744" />
      <origin xyz="0 0.01 -0.06" rpy="0 -0 0"/>
      <inertia ixx="0.000841" ixy="0" ixz="0" iyy="0.000835" iyz="0" izz="0.000305"/>
    </inertial>
  </link>
  <xacro:gazebo_link_reference link_name="r_shoulder_center" />

  <link name="r_upperarm_link">
    <xacro:unless value="${disable_mesh}"> <visual>
      <origin xyz="0 0 0" rpy="0 -0 0"/>
      <geometry>
        <mesh filename="package://seed_r7_description/meshes/typeF_upperbody/RARM_LINK3_mesh.dae" scale="1 1 1" />
      </geometry>
    </visual> </xacro:unless>
    <xacro:unless value="${disable_mesh}"> <collision>
<!--
      <origin xyz="0 0 0" rpy="0 -0 0"/>
      <geometry>
        <mesh filename="package://seed_r7_description/meshes/typeF_upperbody/RARM_LINK3_mesh.dae" scale="1 1 1" />
      </geometry>
 -->
      <origin  xyz="-0.005 0 -0.08" rpy="0 0 0"/>
      <geometry>
        <box size="0.076 0.065 0.18" />
      </geometry>
    </collision> </xacro:unless>
    <inertial>
      <mass value="0.574" />
      <origin xyz="0.005 0 -0.0654" rpy="0 -0 0"/>
      <inertia ixx="0.00214" ixy="0" ixz="0" iyy="0.00217" iyz="0" izz="0.003"/>
    </inertial>
  </link>
  <xacro:gazebo_link_reference link_name="r_upperarm_link" />

  <link name="r_elbow_link">
    <xacro:unless value="${disable_mesh}"> <visual>
      <origin xyz="-0.035 0 -0.035" rpy="0 -0 0"/>
      <geometry>
        <mesh filename="package://seed_r7_description/meshes/typeF_upperbody/RARM_LINK4_mesh.dae" scale="1 1 1" />
      </geometry>
    </visual> </xacro:unless>
    <xacro:unless value="${disable_mesh}"> <collision>
<!--
      <origin xyz="-0.035 0 -0.035" rpy="0 -0 0"/>
      <geometry>
        <mesh filename="package://seed_r7_description/meshes/typeF_upperbody/RARM_LINK4_mesh.dae" scale="1 1 1" />
      </geometry>
 -->
      <origin  xyz="-0.035 0 -0.03" rpy="0 0 0"/>
      <geometry>
        <box size="0.06 0.051 0.075" />
      </geometry>
    </collision> </xacro:unless>
    <inertial>
      <mass value="0.711" />
      <origin xyz="-0.03 0 -0.0546" rpy="0 -0 0"/>
      <inertia ixx="0.00178" ixy="0" ixz="0" iyy="0.00179" iyz="0" izz="0.0035"/>
    </inertial>
  </link>
  <xacro:gazebo_link_reference link_name="r_elbow_link" />

  <link name="r_forearm_link">
    <xacro:unless value="${disable_mesh}"> <visual>
      <origin xyz="0 0 0" rpy="0 0 1.5707963267948966"/>
      <geometry>
        <mesh filename="package://seed_r7_description/meshes/typeF_upperbody/RARM_LINK5_mesh.dae" scale="1 1 1" />
      </geometry>
    </visual> </xacro:unless>
    <xacro:unless value="${disable_mesh}"> <collision>
      <origin xyz="0 0 0" rpy="0 0 1.5707963267948966"/>
      <geometry>
        <mesh filename="package://seed_r7_description/meshes/typeF_upperbody/RARM_LINK5_mesh.dae" scale="1 1 1" />
      </geometry>
    </collision> </xacro:unless>
    <inertial>
      <mass value="0.132" />
      <origin xyz="0.006 0 -0.0738" rpy="0 -0 0"/>
      <inertia ixx="0.0007" ixy="0" ixz="0" iyy="0.0007" iyz="0" izz="0.0004"/>
    </inertial>
  </link>
  <xacro:gazebo_link_reference link_name="r_forearm_link" />

  <link name="r_wrist_center">
    <inertial>
      <mass value="0.05" />
      <origin xyz="0 0 0" rpy="0 -0 0"/>
      <inertia ixx="0.0001" ixy="0" ixz="0" iyy="0.0001" iyz="0" izz="0.0001"/>
    </inertial>
  </link>
  <xacro:gazebo_link_reference link_name="r_wrist_center" />

  <joint name="waist_y_joint" type="revolute">
    <parent link="${base_link}"/>
    <child  link="hip_sphere_link"/>
    <origin xyz="0 0 0.010" rpy="0 -0 0 "/>
    <axis   xyz="0 0 1"/>
    <!-- from -120 to 120 degrees-->
    <limit lower="-2.09" upper="2.09" effort="10" velocity="0.6" />
    <dynamics damping="0.2" friction="0" />
  </joint>
  <xacro:gazebo_transmission joint_name="waist_y_joint" />

  <joint name="waist_p_joint" type="revolute">
    <parent link="hip_sphere_link"/>
    <child  link="hip_center"/>
    <origin xyz="0 0 0.1355" rpy="0 -0 0 "/>
    <axis   xyz="0 1 0"/>
    <!-- from -5 to 35 degrees-->
    <limit lower="-0.087" upper="0.61" effort="10" velocity="0.5" />
    <dynamics damping="0.2" friction="0" />
  </joint>
  <xacro:gazebo_transmission joint_name="waist_p_joint" />

  <joint name="waist_r_joint" type="revolute">
    <parent link="hip_center"/>
    <child  link="body_link"/>
    <origin xyz="0 0 0" rpy="0 -0 0 "/>
    <axis   xyz="1 0 0"/>
    <!-- from -1 to 1 degrees-->
    <limit lower="-0.017" upper="0.017" effort="10" velocity="0.4" />
    <dynamics damping="0.2" friction="0" />
  </joint>
  <xacro:gazebo_transmission joint_name="waist_r_joint" />

  <joint name="l_shoulder_p_joint" type="revolute">
    <parent link="body_link"/>
    <child  link="l_shoulder_link"/>
    <origin xyz="-0.01815 0.1342 0.3049" rpy="0 -0 0 "/>
    <axis   xyz="0 0.984808 -0.173648"/>
    <!-- from -88 to 15 degrees-->
    <limit lower="-1.535" upper="0.261" effort="10" velocity="0.4" />
    <dynamics damping="0.2" friction="0" />
  </joint>
  <xacro:gazebo_transmission joint_name="l_shoulder_p_joint" />

  <joint name="l_shoulder_r_joint" type="revolute">
    <parent link="l_shoulder_link"/>
    <child  link="l_shoulder_center"/>
    <origin xyz="0 0.05978 0.028046" rpy="0 -0 0 "/>
    <axis   xyz="1 0 0"/>
    <!-- from 0 to 90 degrees-->
    <limit lower="0" upper="1.5707" effort="10" velocity="0.6" />
    <dynamics damping="0.2" friction="0" />
  </joint>
  <xacro:gazebo_transmission joint_name="l_shoulder_r_joint" />

  <joint name="l_shoulder_y_joint" type="revolute">
    <parent link="l_shoulder_center"/>
    <child  link="l_upperarm_link"/>
    <origin xyz="0 -0.010 -0.127" rpy="0 -0 0 "/>
    <axis   xyz="0 0 1"/>
    <!-- from -180 to 45 degrees-->
    <limit lower="-1.5707" upper="0.785398" effort="10" velocity="1.2" />
    <dynamics damping="0.2" friction="0" />
  </joint>
  <xacro:gazebo_transmission joint_name="l_shoulder_y_joint" />

  <joint name="l_elbow_joint" type="revolute">
    <parent link="l_upperarm_link"/>
    <child  link="l_elbow_link"/>
    <origin xyz="0.035 0 -0.1625" rpy="0 -0 0 "/>
    <axis   xyz="0 1 0"/>
    <!-- from -171 to 0 degrees-->
    <limit lower="-3.0" upper="0" effort="10" velocity="1.2" />
    <dynamics damping="0.2" friction="0" />
  </joint>
  <xacro:gazebo_transmission joint_name="l_elbow_joint" />

  <joint name="l_wrist_y_joint" type="revolute">
    <parent link="l_elbow_link"/>
    <child  link="l_forearm_link"/>
    <origin xyz="-0.035 0 -0.070" rpy="0 -0 0 "/>
    <axis   xyz="0 0 1"/>
    <!-- from -180 to 180 degrees-->
    <limit lower="-1.5707" upper="1.5707" effort="10" velocity="1.3" />
    <dynamics damping="0.2" friction="0" />
  </joint>
  <xacro:gazebo_transmission joint_name="l_wrist_y_joint" />

  <joint name="l_wrist_p_joint" type="revolute">
    <parent link="l_forearm_link"/>
    <child  link="l_wrist_center"/>
    <origin xyz="0 0 -0.1955" rpy="0 -0 0 "/>
    <axis   xyz="0 1 0"/>
    <!-- from -5 to 5 degrees-->
    <limit lower="-0.087" upper="0.087" effort="10" velocity="0.9" />
    <dynamics damping="0.2" friction="0" />
  </joint>
  <xacro:gazebo_transmission joint_name="l_wrist_p_joint" />

  <joint name="l_wrist_r_joint" type="revolute">
    <parent link="l_wrist_center"/>
    <child  link="${l_hand_link}"/>
    <origin xyz="0 0 0" rpy="0 -0 0 "/>
    <axis   xyz="1 0 0"/>
    <!-- from -85 to 25 degrees-->
    <limit lower="-1.484" upper="0.436" effort="10" velocity="2.1" />
    <dynamics damping="0.2" friction="0" />
  </joint>
  <xacro:gazebo_transmission joint_name="l_wrist_r_joint" />

  <joint name="neck_y_joint" type="revolute">
    <parent link="body_link"/>
    <child  link="neck_link"/>
    <origin xyz="0 0 0.3535" rpy="0 -0 0 "/>
    <axis   xyz="0 0 1"/>
    <!-- from -120 to 120 degrees-->
    <limit lower="-2.09" upper="2.09" effort="10" velocity="1.6" />
    <dynamics damping="0.2" friction="0" />
  </joint>
  <xacro:gazebo_transmission joint_name="neck_y_joint" />

  <joint name="neck_p_joint" type="revolute">
    <parent link="neck_link"/>
    <child  link="head_base_link"/>
    <origin xyz="0 0 0.1045" rpy="0 -0 0 "/>
    <axis   xyz="0 1 0"/>
    <!-- from -15 to 55 degrees-->
    <limit lower="-0.262" upper="0.96" effort="10" velocity="2.1" />
    <dynamics damping="0.2" friction="0" />
  </joint>
  <xacro:gazebo_transmission joint_name="neck_p_joint" />

  <joint name="neck_r_joint" type="revolute">
    <parent link="head_base_link"/>
    <child  link="head_link"/>
    <origin xyz="0 0 0" rpy="0 -0 0 "/>
    <axis   xyz="1 0 0"/>
    <!-- from -5 to 5 degrees-->
    <limit lower="-0.087" upper="0.087" effort="10" velocity="0.9" />
    <dynamics damping="0.2" friction="0" />
  </joint>
  <xacro:gazebo_transmission joint_name="neck_r_joint" />

  <joint name="r_shoulder_p_joint" type="revolute">
    <parent link="body_link"/>
    <child  link="r_shoulder_link"/>
    <origin xyz="-0.01815 -0.1342 0.3049" rpy="0 -0 0 "/>
    <axis   xyz="0 0.984808 0.173648"/>
    <!-- from -88 to 15 degrees-->
    <limit lower="-1.535" upper="0.261" effort="10" velocity="0.4" />
    <dynamics damping="0.2" friction="0" />
  </joint>
  <xacro:gazebo_transmission joint_name="r_shoulder_p_joint" />

  <joint name="r_shoulder_r_joint" type="revolute">
    <parent link="r_shoulder_link"/>
    <child  link="r_shoulder_center"/>
    <origin xyz="0 -0.059778 0.028046" rpy="0 -0 0 "/>
    <axis   xyz="1 0 0"/>
    <!-- from -90 to 0 degrees-->
    <limit lower="-1.5707" upper="0" effort="10" velocity="0.6" />
    <dynamics damping="0.2" friction="0" />
  </joint>
  <xacro:gazebo_transmission joint_name="r_shoulder_r_joint" />

  <joint name="r_shoulder_y_joint" type="revolute">
    <parent link="r_shoulder_center"/>
    <child  link="r_upperarm_link"/>
    <origin xyz="0 0.010 -0.127" rpy="0 -0 0 "/>
    <axis   xyz="0 0 1"/>
    <!-- from -45 to 180 degrees-->
    <limit lower="-0.785398" upper="1.5707" effort="10" velocity="1.2" />
    <dynamics damping="0.2" friction="0" />
  </joint>
  <xacro:gazebo_transmission joint_name="r_shoulder_y_joint" />

  <joint name="r_elbow_joint" type="revolute">
    <parent link="r_upperarm_link"/>
    <child  link="r_elbow_link"/>
    <origin xyz="0.035 0 -0.1625" rpy="0 -0 0 "/>
    <axis   xyz="0 1 0"/>
    <!-- from -171 to 0 degrees-->
    <limit lower="-3.0" upper="0" effort="10" velocity="1.2" />
    <dynamics damping="0.2" friction="0" />
  </joint>
  <xacro:gazebo_transmission joint_name="r_elbow_joint" />

  <joint name="r_wrist_y_joint" type="revolute">
    <parent link="r_elbow_link"/>
    <child  link="r_forearm_link"/>
    <origin xyz="-0.035 0 -0.070" rpy="0 -0 0 "/>
    <axis   xyz="0 0 1"/>
    <!-- from -180 to 180 degrees-->
    <limit lower="-1.5707" upper="1.5707" effort="10" velocity="1.3" />
    <dynamics damping="0.2" friction="0" />
  </joint>
  <xacro:gazebo_transmission joint_name="r_wrist_y_joint" />

  <joint name="r_wrist_p_joint" type="revolute">
    <parent link="r_forearm_link"/>
    <child  link="r_wrist_center"/>
    <origin xyz="0 0 -0.1955" rpy="0 -0 0 "/>
    <axis   xyz="0 1 0"/>
    <!-- from -5 to 5 degrees-->
    <limit lower="-0.087" upper="0.087" effort="10" velocity="0.9" />
    <dynamics damping="0.2" friction="0" />
  </joint>
  <xacro:gazebo_transmission joint_name="r_wrist_p_joint" />

  <joint name="r_wrist_r_joint" type="revolute">
    <parent link="r_wrist_center"/>
    <child  link="${r_hand_link}"/>
    <origin xyz="0 0 0" rpy="0 -0 0 "/>
    <axis   xyz="1 0 0"/>
    <!-- from -25 to 85 degrees-->
    <limit lower="-0.436" upper="1.484" effort="10" velocity="2.1" />
    <dynamics damping="0.2" friction="0" />
  </joint>
  <xacro:gazebo_transmission joint_name="r_wrist_r_joint" />
  </xacro:macro>
</robot>
