<?xml version="1.0"?>

<!-- XML namespaces -->
<robot name="hand_yaw" xmlns:xacro="http://ros.org/wiki/xacro">

  <xacro:property name="M_PI" value="3.1415926535897931" />
  <xacro:include filename="$(find seed_r7_description)/urdf/gazebo.xacro" />

  <xacro:macro name="hand_yaw" params="prefix:=r reflect:=1 hand_link disable_mesh:=false">
  <!-- ============================   hand_yaw   ============================ -->
    <!-- prefix is "r" or "l" -->
    <!-- reflect=1 is rightside, reflect=-1 is leftside -->
  <link name="${prefix}_hand_yaw_link">
    <xacro:unless value="${disable_mesh}"> <visual>
      <origin xyz="0.0 0 0" rpy="0 ${M_PI / 2.0} ${reflect * M_PI / 2.0}"/>
      <geometry>
        <mesh filename="package://seed_r7_description/meshes/hand_yaw/wrist.dae" scale="1 1 1" />
      </geometry>
    </visual> </xacro:unless>
    <xacro:unless value="${disable_mesh}"> <collision>
      <origin xyz="0 0 0" rpy="0 ${M_PI / 2.0} ${reflect * M_PI / 2.0}"/>
      <geometry>
        <mesh filename="package://seed_r7_description/meshes/hand_yaw/wrist.dae" scale="1 1 1" />
      </geometry>
    </collision> </xacro:unless>
    <inertial>
      <mass value="0.183" />
      <!-- original version -->
      <!--origin xyz="0 0 -0.0875" rpy="0 -0 0"/>
      <inertia ixx="0.000601" ixy="0" ixz="0" iyy="0.00055" iyz="0" izz="0.000102"/-->
      <!-- just fixed for gazebo / aim to increase z axis inertia-->
      <origin xyz="0 0.014 -0.02" rpy="0 -0 0"/>
      <inertia ixx="0.0005" ixy="0" ixz="0" iyy="0.0005" iyz="0" izz="0.0007" />
    </inertial>
  </link>
  <gazebo reference="${prefix}_hand_yaw_link">
    <mu1>0.9</mu1>
    <mu2>0.9</mu2>
  </gazebo>

  <joint name="${prefix}_hand_y_joint" type="revolute">
    <parent link="${prefix}_hand_yaw_link"/>
    <child  link="${hand_link}"/>
    <origin xyz="0 0 -0.04" rpy="0 0 0"/>
    <axis   xyz="0 0 1"/>
    <limit lower="-2.0" upper="2.0" effort="100" velocity="3.1" />
    <dynamics damping="0.2" friction="0" />
  </joint>
  <xacro:gazebo_transmission joint_name="${prefix}_hand_y_joint" />

  </xacro:macro>
</robot>
