<?xml version="1.0"?>

<!-- XML namespaces -->
<robot name="trx_s" xmlns:xacro="http://ros.org/wiki/xacro">

  <xacro:property name="M_PI" value="3.1415926535897931" />
  <xacro:include filename="$(find seed_r7_description)/urdf/gazebo.xacro" />

  <xacro:macro name="trx_s" params="prefix:=r reflect:=1 disable_mesh:=false">
  <!-- ============================   Hand(trx_s)   ============================ -->
    <!-- prefix is "r" or "l" -->
    <!-- reflect=1 is rightside, reflect=-1 is leftside -->

  <link name="${prefix}_hand_link">
    <xacro:unless value="${disable_mesh}"> <visual>
      <origin xyz="0 0 0" rpy="0 -0 ${(1.0 - reflect) * M_PI / 2.0}"/>
      <geometry>
        <mesh filename="package://seed_r7_description/meshes/trx_s/RARM_LINK7_mesh.dae" scale="1 1 1" />
      </geometry>
    </visual> </xacro:unless>
    <xacro:unless value="${disable_mesh}">
    <collision>
      <origin rpy="${reflect * 0.7} 0 0" xyz="0 0 -0.093"/>
      <geometry>
        <box size="0.036 0.070 0.030" />
      </geometry>
    </collision>
    <collision>
      <origin rpy="${reflect * -0.10} 0 0" xyz="0 ${reflect * -0.007} -0.055"/>
      <geometry>
        <box size="0.036 0.050 0.070" />
      </geometry>
    </collision>
    </xacro:unless>
    <inertial>
      <mass value="0.183" />
      <origin xyz="0 0 -0.0875" rpy="0 -0 0"/>
      <inertia ixx="0.000601" ixy="0" ixz="0" iyy="0.00055" iyz="0" izz="0.000102"/>
    </inertial>
  </link>
  <xacro:gazebo_link_reference link_name="${prefix}_hand_link" />

  <link name="${prefix}_indexbase_link">
    <xacro:unless value="${disable_mesh}"> <visual>
      <origin xyz="0 ${0.013 * reflect} 0.115" rpy="0 -0 ${(1.0 - reflect) * M_PI / 2.0}"/>
      <geometry>
        <mesh filename="package://seed_r7_description/meshes/trx_s/RARM_INDEX_LINK1_mesh.dae" scale="1 1 1" />
      </geometry>
    </visual> </xacro:unless>
    <xacro:unless value="${disable_mesh}"> <collision>
      <origin xyz="0.015 ${reflect * 0.013494 } -0.021422" rpy="${reflect * -0.85} 0 0"/>
      <geometry>
        <box size="0.01 0.061 0.016" />  <!-- 0.85 -->
      </geometry>
    </collision>
    <collision>
      <origin xyz="-0.015 ${reflect * 0.013494 } -0.021422" rpy="${reflect * -0.85} 0 0"/>
      <geometry>
        <box size="0.01 0.061 0.016" />  <!-- 0.85 -->
      </geometry>
    </collision> </xacro:unless>
    <inertial>
      <mass value="0.1" />
      <origin xyz="0 ${reflect * 0.014} -0.021" rpy="0 0 0"/>
      <inertia ixx="0.001" iyy="0.0001" izz="0.0001" ixy="0" ixz="0" iyz="0" />
    </inertial>
  </link>
  <xacro:gazebo_link_reference link_name="${prefix}_indexbase_link" />

  <link name="${prefix}_indexmid_link">
    <xacro:unless value="${disable_mesh}"> <visual>
      <origin xyz="0 ${-0.015754 * reflect} 0.149615" rpy="0 -0 ${(1.0 - reflect) * M_PI / 2.0}"/>
      <geometry>
        <mesh filename="package://seed_r7_description/meshes/trx_s/RARM_INDEX_LINK2_mesh.dae" scale="1 1 1" />
      </geometry>
    </visual> </xacro:unless>
    <xacro:unless value="${disable_mesh}"> <collision>
      <origin xyz="0.015 ${reflect * 0.014} -0.008" rpy="${reflect * -0.3} 0 0"/> <!-- 0.3 -->
      <geometry>
        <box size="0.01 0.030 0.016" />
      </geometry>
    </collision>
    <collision>
      <origin xyz="-0.015 ${reflect * 0.014} -0.008" rpy="${reflect * -0.3} 0 0"/> <!-- 0.3 -->
      <geometry>
        <box size="0.01 0.030 0.016" />
      </geometry>
    </collision> </xacro:unless>
    <inertial>
      <mass value="0.1" />
      <origin xyz="0 ${reflect * 0.014} -0.008" rpy="0 0 0"/>
      <inertia ixx="0.001" iyy="0.0001" izz="0.0001" ixy="0" ixz="0" iyz="0" />
    </inertial>
  </link>
  <xacro:gazebo_link_reference link_name="${prefix}_indexmid_link" />

  <link name="${prefix}_indexend_link">
    <xacro:unless value="${disable_mesh}"> <visual>
      <origin xyz="0 ${-0.03747 * reflect} 0.162972" rpy="0 -0 ${(1.0 - reflect) * M_PI / 2.0}"/>
      <geometry>
        <mesh filename="package://seed_r7_description/meshes/trx_s/RARM_INDEX_LINK3_mesh.dae" scale="1 1 1" />
      </geometry>
    </visual> </xacro:unless>
    <xacro:unless value="${disable_mesh}"> <collision>
      <origin xyz="0.015 ${reflect * 0.013} 0.004" rpy="0 0 0"/> <!-- 0.0 -->
      <geometry>
        <box size="0.01 0.028 0.016" />
      </geometry>
    </collision>
    <collision>
      <origin xyz="-0.015 ${reflect * 0.013} 0.004" rpy="0 0 0"/> <!-- 0.0 -->
      <geometry>
        <box size="0.01 0.028 0.016" />
      </geometry>
    </collision> </xacro:unless>
    <inertial>
      <mass value="0.1" />
      <origin xyz="0 ${reflect * 0.02} 0" rpy="0 0 0"/>
      <inertia ixx="0.0001" iyy="0.0001" izz="0.0001" ixy="0" ixz="0" iyz="0" />
    </inertial>
  </link>
  <xacro:gazebo_link_reference link_name="${prefix}_indexend_link" />

  <link name="${prefix}_thumb_link">
    <xacro:unless value="${disable_mesh}"> <visual>
      <origin xyz="0 ${-0.022355 * reflect} 0.079645" rpy="0 -0 ${(1.0 - reflect) * M_PI / 2.0}"/>
      <geometry>
        <mesh filename="package://seed_r7_description/meshes/trx_s/RARM_THUMB_LINK_mesh.dae" scale="1 1 1" />
      </geometry>
    </visual> </xacro:unless>
    <xacro:unless value="${disable_mesh}">
    <collision>
      <origin rpy="${reflect * 0.63} 0 0" xyz="0.0 ${reflect * 0.019645} -0.010355"/>
      <geometry>
        <box size="0.012 0.008 0.050"/>
      </geometry>
    </collision>
    <collision>
      <origin rpy="${reflect * 0.1} 0 0" xyz="0.0 ${reflect * 0.035645} -0.050355"/>
      <geometry>
        <box size="0.012 0.008 0.050"/>
      </geometry>
    </collision>
    </xacro:unless>
    <inertial>
      <mass value="0.1" />
      <origin xyz="0 ${reflect * 0.05} -0.06" rpy="0 0 0"/>
      <inertia ixx="0.001" iyy="0.0001" izz="0.0001" ixy="0" ixz="0" iyz="0" />
    </inertial>
  </link>
  <xacro:gazebo_link_reference link_name="${prefix}_thumb_link" />

  <joint name="${prefix}_indexbase_joint" type="continuous">
    <parent link="${prefix}_hand_link"/>
    <child  link="${prefix}_indexbase_link"/>
    <origin xyz="0 ${-0.013 * reflect} -0.115" rpy="0 -0 0 "/>
    <axis   xyz="1 0 0"/>
    <mimic joint="${prefix}_thumb_joint" multiplier="-1" offset="0"/>
  </joint>

  <joint name="${prefix}_indexmid_joint" type="fixed">
    <parent link="${prefix}_indexbase_link"/>
    <child  link="${prefix}_indexmid_link"/>
    <origin xyz="0 ${0.028754 * reflect} -0.034615" rpy="0 -0 0 "/>
  </joint>

  <joint name="${prefix}_indexend_joint" type="fixed">
    <parent link="${prefix}_indexmid_link"/>
    <child  link="${prefix}_indexend_link"/>
    <origin xyz="0 ${0.021716 * reflect} -0.013357" rpy="0 -0 0 "/>
  </joint>

  <joint name="${prefix}_thumb_joint" type="revolute">
    <parent link="${prefix}_hand_link"/>
    <child  link="${prefix}_thumb_link"/>
    <origin xyz="0 ${0.022355 * reflect} -0.079645" rpy="0 -0 0 "/>
    <axis   xyz="1 0 0"/>
    <limit lower="-1.0" upper="1.0" effort="50" velocity="0.5" />
    <dynamics damping="0.2" friction="0" />
  </joint>
  <xacro:gazebo_transmission joint_name="${prefix}_thumb_joint" />

  <!-- for ik eef link-->
  <link name="${prefix}_eef_grasp_link"/>
  <link name="${prefix}_eef_pick_link"/>
  <link name="${prefix}_thumb_tip_link"/>
  <link name="${prefix}_index_tip_link"/>
  <!-- for ik eef link-->

  <!-- for ik eef connector-->
  <joint name="${prefix}_eef_grasp_joint" type="fixed">
    <parent  link="${prefix}_hand_link"/>
    <child link="${prefix}_eef_grasp_link"/>
    <origin xyz="0.0 ${0.04 * reflect} -0.14" rpy="${-0.2618 * reflect} 1.5708 0 "/>
  </joint>
  <joint name="${prefix}_eef_pick_joint" type="fixed">
    <parent  link="${prefix}_hand_link"/>
    <child link="${prefix}_eef_pick_link"/>
    <origin xyz="0.0 ${0.07 * reflect} -0.16" rpy="0 1.5708 0 "/>
  </joint>
  <joint name="${prefix}_thumb_tip_joint" type="fixed">
    <parent  link="${prefix}_thumb_link"/>
    <child link="${prefix}_thumb_tip_link"/>
    <origin xyz="0.0 ${0.035 * reflect} -0.085" rpy="0 0 0 "/>
  </joint>
  <joint name="${prefix}_index_tip_joint" type="fixed">
    <parent  link="${prefix}_indexend_link"/>
    <child link="${prefix}_index_tip_link"/>
    <origin xyz="0.0 ${0.02 * reflect} 0.0" rpy="0 0 0 "/>
  </joint>
  <!-- for ik eef connector-->

  </xacro:macro>
</robot>
