<?xml version="1.0" ?>
<sdf version="1.5">
  <world name="default">
    <gui>
      <camera name="user_camera">
        <pose>-5 -7 4 0 0.54 0.76</pose>
      </camera>
    </gui>
    <physics type='ode'>
      <real_time_factor>1</real_time_factor>
      <real_time_update_rate>0.0</real_time_update_rate>
      <max_step_size>0.002</max_step_size>
    </physics>
    <scene>
      <ambient>0.7 0.7 0.7 1</ambient>
      <background>0.1 0.1 0.1 1</background>
    </scene>
    <include>
      <uri>model://sun</uri>
    </include>
    <include>
      <uri>model://ground_plane</uri>
    </include>
    <include>
      <uri>model://2nd_floor</uri>
      <pose>0 0 0 0 0 0</pose>
      <static>true</static>
    </include>

<!--  ******* showroom *************  -->
    <include>
      <name>front</name>
      <uri>model://front</uri>
      <static>true</static>
      <pose>2.2 0.7 0 0 0 -1.57</pose>
    </include>
    <include>
      <name>meeting_table</name>
      <uri>model://meeting_table</uri>
      <pose>3.5 -5.5 0 0 0 -1.57</pose>
    </include>

<!--  ******* cafeteria *************  -->
    <include>
      <name>table_set1</name>
      <uri>model://table_set</uri>
      <pose>8 5 0 0 0 0</pose>
    </include>
    <include>
      <name>table_set2</name>
      <uri>model://table_set</uri>
      <pose>8 0 0 0 0 0</pose>
    </include>
    <include>
      <name>table_set3</name>
      <uri>model://table_set</uri>
      <pose>8 -5 0 0 0 0</pose>
    </include>
    <include>
      <name>table_set4</name>
      <uri>model://table_set</uri>
      <pose>14 5 0 0 0 0</pose>
    </include>
    <include>
      <name>table_set5</name>
      <uri>model://table_set</uri>
      <pose>14 0 0 0 0 0</pose>
    </include>
    <include>
      <name>table_set6</name>
      <uri>model://table_set</uri>
      <pose>14 -5 0 0 0 0</pose>
    </include>

<!--  ******* experimental room *************  -->

    <include>
      <name>shelf-1</name>
      <uri>model://shelf</uri>
      <pose>0.34 -1 0 0 0 -1.57</pose>
    </include>
    <include>
      <name>slef2</name>
      <uri>model://shelf2</uri>
      <pose>-0.61 -1 0 0 0 -1.57</pose>
    </include>
    <include>
      <name>slef3</name>
      <uri>model://shelf3</uri>
      <pose>-1.56 -1 0 0 0 -1.57</pose>
    </include>

    <include>
      <name>half_table_set1</name>
      <uri>model://half_table_set</uri>
      <pose>-0.1 -3.0 0 0 0 -1.57</pose>
    </include>
    <include>
      <name>half_table_set2</name>
      <uri>model://half_table_set</uri>
      <pose>-1.9 -3.0 0 0 0 -1.57</pose>
    </include>
    <include>
      <name>long_table</name>
      <uri>model://long_table</uri>
      <pose>-2.5 -4.2 0 0 0 0</pose>
    </include>

    <include>
      <name>shelf-2</name>
      <uri>model://shelf</uri>
      <pose>0.58 -5 0 0 0 3.14</pose>
    </include>

    <include>
      <name>chair</name>
      <uri>model://chair</uri>
      <pose>-2.9 -4.2 0 0 0 0</pose>
    </include>

<!-- *************  auto door   **************** -->

    <!-- World plugin that publishes event messages.
         The topics used in these messages match up with topics used by the
         plugin in the elevator model below.
    -->
    <plugin filename="libSimEventsPlugin.so" name="elevator_event_plugin">
      <!-- Region on the ground floor, in front of the elevator -->
      <region>
        <name>region1</name>
        <volume>
          <min>0.5 -6 0</min>
          <max>2.5 -9 1</max>
        </volume>
      </region>

      <!-- Region on the first floor, in front of the elevator -->
      <region>
        <name>region2</name>
        <volume>
          <min>0.5 -7 3</min>
          <max>2.5 -9 4</max>
        </volume>
      </region>

      <!-- Event publisher for ground floor-->
      <event>
        <name>region1_event</name>
        <type>occupied</type>
        <region>region1</region>
        <topic>~/elevator</topic>
        <msg_data>0</msg_data>
      </event>

      <!-- Event publisher for first floor-->
      <event>
        <name>region2_event</name>
        <type>occupied</type>
        <region>region2</region>
        <topic>~/elevator</topic>
        <msg_data>1</msg_data>
      </event>
    </plugin>

    <!-- The elevator car -->
    <model name="elevator">
      <pose>0 0 0.075 0 0 0</pose>
      <link name="link">
        <inertial>
          <mass>800</mass>
        </inertial>
        <!-- wall1_collision is the wall to the right of the door, when
             facing the door -->
        <collision name="wall1_collision">
          <pose>2.7 -7.8 1.2 0 0 0</pose>
          <geometry>
            <box>
              <size>1.2 0.1 2.5</size>
            </box>
          </geometry>
        </collision>
        <visual name="wall1_visual">
          <pose>2.7 -7.8 1.2 0 0 0</pose> 
          <geometry>
            <box>
              <size>1.2 0.1 2.5</size>
            </box>
          </geometry>
          <material>
            <script>
              <name>Gazebo/Red</name>
            </script>
          </material>
        </visual>
  
        <!-- wall2_collision is the wall to the left of the door, when
             facing the door -->
        <collision name="wall2_collision">
          <pose>1.0 -7.8 1.2 0 0 0</pose> 
          <geometry>
            <box>
              <size>0.125 0.1 2.5</size>
            </box>
          </geometry>
        </collision>
        <visual name="wall2_visual">
          <pose>1.0 -7.8 1.2 0 0 0</pose> 
          <geometry>
            <box>
              <size>0.125 0.1 2.5</size>
            </box>
          </geometry>
          <material>
            <script>
              <name>Gazebo/Red</name>
            </script>
          </material>
        </visual>
      </link>
  
      <link name="door">
        <pose>1.6 -7.8 1.2 0 0 0</pose> 
        <collision name="collision">
          <geometry>
            <box>
              <size>1.0 0.08 2.5</size>
            </box>
          </geometry>
        </collision>
        <visual name="visual">
          <geometry>
            <box>
              <size>1.0 0.08 2.5</size>
            </box>
          </geometry>
        </visual>
      </link>
    
      <joint name="door" type="prismatic">
        <parent>link</parent>
        <child>door</child>
        <axis>
          <xyz>1 0 0</xyz>
          <limit>
            <lower>0</lower>
            <upper>1</upper>
            <effort>10</effort>
          </limit>

          <dynamics>
            <damping>2</damping>
          </dynamics>
        </axis>
      </joint>

      <joint name="lift" type="prismatic">
        <parent>world</parent>
        <child>link</child>
        <axis>
          <xyz>0 0 1</xyz>
          <limit>
            <lower>0</lower>
            <upper>10</upper>
            <effort>100000</effort>
          </limit>
  
          <dynamics>
            <damping>50</damping>
          </dynamics>
        </axis>
        <physics>
          <ode>
            <implicit_spring_damper>1</implicit_spring_damper>
          </ode>
        </physics>
      </joint>

      <!-- Plugin to control the elevator -->
      <plugin filename="libElevatorPlugin.so" name="elevator_plugin">
        <lift_joint>elevator::lift</lift_joint>
        <door_joint>elevator::door</door_joint>
        <floor_height>3.075</floor_height>

        <!-- Time the elevator door will stay open in seconds -->
        <door_wait_time>5</door_wait_time>

        <!-- This topic is used to control the elevator -->
        <topic>~/elevator</topic>
      </plugin>
    </model>

  </world>
</sdf>

